Workbook

Sheet Resumen
B2: Modelo de Inversión en Alerta Temprana vs Costes de Catástrofes Naturales
B3: Análisis comparativo por región | Datos base: Aon, Swiss Re, Munich Re, EM-DAT, WMO/UNDRR, World Bank
B5: KPIs por Región (Escenario Base)
B7: Región | C7: Pérdidas Hist. Prom. ($B) | D7: Inversión EWS ($B) | E7: Pérdidas Evitadas 10 años ($B) | F7: Ahorro First Responders ($B) | G7: Beneficio Total ($B) | H7: Coste Total EWS ($B) | I7: ROI Proyectado | J7: BCR | K7: Reducción % PIB
B8: Norteamérica | C8: ='Datos Históricos'!I6 -> 195 | D8: =Supuestos!C26 -> 8 | E8: =C8*0.17*10 -> 331.5 | F8: =C8*0.08*0.17*10 -> 26.52 | G8: =E8+F8 -> 358.02 | H8: =D8*(1+0.15*10) -> 20 | I8: =(G8-H8)/H8 -> 16.901 | J8: =G8/H8 -> 17.901 | K8: =E8/Supuestos!E26 -> 0.009954955
B9: Sudamérica | C9: ='Datos Históricos'!I7 -> 16.4 | D9: =Supuestos!C27 -> 3 | E9: =C9*0.17*10 -> 27.88 | F9: =C9*0.08*0.17*10 -> 2.2304 | G9: =E9+F9 -> 30.1104 | H9: =D9*(1+0.15*10) -> 7.5 | I9: =(G9-H9)/H9 -> 3.01472 | J9: =G9/H9 -> 4.01472 | K9: =E9/Supuestos!E27 -> 0.0061955556
B10: Asia | C10: ='Datos Históricos'!I8 -> 76.2 | D10: =Supuestos!C28 -> 10 | E10: =C10*0.17*10 -> 129.54 | F10: =C10*0.08*0.17*10 -> 10.3632 | G10: =E10+F10 -> 139.9032 | H10: =D10*(1+0.15*10) -> 25 | I10: =(G10-H10)/H10 -> 4.596128 | J10: =G10/H10 -> 5.596128 | K10: =E10/Supuestos!E28 -> 0.0037011429
B11: Europa Occidental | C11: ='Datos Históricos'!I9 -> 21 | D11: =Supuestos!C29 -> 5 | E11: =C11*0.17*10 -> 35.7 | F11: =C11*0.08*0.17*10 -> 2.856 | G11: =E11+F11 -> 38.556 | H11: =D11*(1+0.15*10) -> 12.5 | I11: =(G11-H11)/H11 -> 2.08448 | J11: =G11/H11 -> 3.08448 | K11: =E11/Supuestos!E29 -> 0.002975
B12: Europa Meridional | C12: ='Datos Históricos'!I10 -> 8.4 | D12: =Supuestos!C30 -> 2.5 | E12: =C12*0.17*10 -> 14.28 | F12: =C12*0.08*0.17*10 -> 1.1424 | G12: =E12+F12 -> 15.4224 | H12: =D12*(1+0.15*10) -> 6.25 | I12: =(G12-H12)/H12 -> 1.467584 | J12: =G12/H12 -> 2.467584 | K12: =E12/Supuestos!E30 -> 0.0031733333
B13: Europa Oriental | C13: ='Datos Históricos'!I11 -> 22.6 | D13: =Supuestos!C31 -> 2.5 | E13: =C13*0.17*10 -> 38.42 | F13: =C13*0.08*0.17*10 -> 3.0736 | G13: =E13+F13 -> 41.4936 | H13: =D13*(1+0.15*10) -> 6.25 | I13: =(G13-H13)/H13 -> 5.638976 | J13: =G13/H13 -> 6.638976 | K13: =E13/Supuestos!E31 -> 0.0064033333
B14: África | C14: ='Datos Históricos'!I12 -> 6.8 | D14: =Supuestos!C32 -> 4 | E14: =C14*0.17*10 -> 11.56 | F14: =C14*0.08*0.17*10 -> 0.9248 | G14: =E14+F14 -> 12.4848 | H14: =D14*(1+0.15*10) -> 10 | I14: =(G14-H14)/H14 -> 0.24848 | J14: =G14/H14 -> 1.24848 | K14: =E14/Supuestos!E32 -> 0.0038533333
B15: Oceanía y Resto | C15: ='Datos Históricos'!I13 -> 13.6 | D15: =Supuestos!C33 -> 1.5 | E15: =C15*0.17*10 -> 23.12 | F15: =C15*0.08*0.17*10 -> 1.8496 | G15: =E15+F15 -> 24.9696 | H15: =D15*(1+0.15*10) -> 3.75 | I15: =(G15-H15)/H15 -> 5.65856 | J15: =G15/H15 -> 6.65856 | K15: =E15/Supuestos!E33 -> 0.01156
B16: TOTAL GLOBAL | C16: =SUM(C8:C15) -> 360 | D16: =SUM(D8:D15) -> 36.5 | E16: =SUM(E8:E15) -> 612 | F16: =SUM(F8:F15) -> 48.96 | G16: =SUM(G8:G15) -> 660.96 | H16: =SUM(H8:H15) -> 91.25 | I16: =(G16-H16)/H16 -> 6.2433973 | J16: =G16/H16 -> 7.2433973 | K16: =E16/SUM(Supuestos!E26:E33) -> 0.0061016949
B19: Métricas Globales de Referencia
B20: Pérdidas económicas globales 2024 ($B) | C20: 397 | D20: Fuente: Aon
B21: Pérdidas económicas globales 2025 ($B) | C21: 260 | D21: Fuente: Aon
B22: Pérdidas aseguradas globales 2025 ($B) | C22: 127 | D22: Fuente: Aon
B23: Brecha de protección global | C23: 0.51 | D23: Fuente: Aon
B24: ROI documentado EWS (WMO/ONU) | C24: 10x | D24: Fuente: WMO/UNDRR
B25: Reducción de daños con 24h aviso | C25: 0.3 | D25: Fuente: ONU
B26: Mortalidad con EWS vs sin EWS | C26: 6-8x menor | D26: Fuente: UNDRR
B27: BCR adaptación (McKinsey) | C27: 3:1 - 7:1 | D27: Fuente: McKinsey/HBS
B28: Inversición EW4All ONU ($B) | C28: 3.1 | D28: Fuente: ONU

Sheet Supuestos
B2: Supuestos del Modelo
B3: Celdas en azul = inputs editables. Celdas en verde = enlaces a otras hojas.
B5: Parámetros por Escenario
B6: Parámetro | C6: Conservador | D6: Base | E6: Optimista | F6: Notas
B7: % Reducción de pérdidas por EWS | C7: 0.1 | D7: 0.2 | E7: 0.3 | F7: Rango internacional: 5%-30% (WMO, LSE, ONU)
B8: % Ahorro en first responders | C8: 0.1 | D8: 0.2 | E8: 0.3 | F8: Estimación: respuesta más rápida reduce costes directos
B9: Años para adopción completa | C9: 5 | D9: 4 | E9: 3 | F9: Tiempo hasta despliegue completo del EWS
B10: Tasa de descuento | C10: 0.07 | D10: 0.06 | E10: 0.05 | F10: Para cálculo de VAN
B11: Horizonte de análisis (años) | C11: 10 | D11: 10 | E11: 10 | F11: Período de proyección del modelo
B12: O&M anual como % del capex | C12: 0.15 | D12: 0.15 | E12: 0.15 | F12: Operación y mantenimiento anual del EWS
B13: % Costes first responders sobre pérdidas | C13: 0.08 | D13: 0.08 | E13: 0.08 | F13: Costes de respuesta directa como % de pérdidas
B15: Parámetros del Escenario Activo (columna Base)
B16: % Reducción de pérdidas (activo) | C16: =D7 -> 0.2
B17: % Ahorro first responders (activo) | C17: =D8 -> 0.2
B18: Años ramp-up (activo) | C18: =D9 -> 4
B19: Tasa de descuento (activa) | C19: =D10 -> 0.06
B20: Horizonte (activo) | C20: =D11 -> 10
B21: O&M % (activo) | C21: =D12 -> 0.15
B22: FR cost % (activo) | C22: =D13 -> 0.08
B24: Inversión EWS y PIB por Región
B25: Región | C25: Inversión EWS ($B) | D25: O&M Anual ($B) | E25: PIB Región ($B) | F25: Fuente
B26: Norteamérica | C26: 8 | D26: =C26*$D$12 -> 1.2 | E26: 33300 | F26: World Bank 2024
B27: Sudamérica | C27: 3 | D27: =C27*$D$12 -> 0.45 | E27: 4500 | F27: World Bank 2024
B28: Asia | C28: 10 | D28: =C28*$D$12 -> 1.5 | E28: 35000 | F28: World Bank 2024
B29: Europa Occidental | C29: 5 | D29: =C29*$D$12 -> 0.75 | E29: 12000 | F29: World Bank 2024
B30: Europa Meridional | C30: 2.5 | D30: =C30*$D$12 -> 0.375 | E30: 4500 | F30: World Bank 2024
B31: Europa Oriental | C31: 2.5 | D31: =C31*$D$12 -> 0.375 | E31: 6000 | F31: World Bank 2024
B32: África | C32: 4 | D32: =C32*$D$12 -> 0.6 | E32: 3000 | F32: World Bank 2024
B33: Oceanía y Resto | C33: 1.5 | D33: =C33*$D$12 -> 0.225 | E33: 2000 | F33: World Bank 2024
B34: TOTAL | C34: =SUM(C26:C33) -> 36.5 | D34: =SUM(D26:D33) -> 5.475 | E34: =SUM(E26:E33) -> 100300

Sheet Datos Históricos
B2: Pérdidas Históricas por Catástrofes Naturales (2021-2025)
B3: Fuente: Aon, Swiss Re, Munich Re, EM-DAT, NOAA. Valores en miles de millones de USD ($B).
B5: Región | C5: 2021 | D5: 2022 | E5: 2023 | F5: 2024 | G5: 2025 | H5: Promedio | I5: % Total | J5: PIB ($B) | K5: % PIB
B6: Norteamérica | C6: 170 | D6: 165 | E6: 195 | F6: 280 | G6: 165 | I6: =AVERAGE(C6:G6) -> 195 | J6: =I6/SUM($I$6:$I$13) -> 0.54166667 | K6: 33300 | L6: =I6/K6 -> 0.0058558559
B7: Sudamérica | C7: 10 | D7: 15 | E7: 12 | F7: 20 | G7: 25 | I7: =AVERAGE(C7:G7) -> 16.4 | J7: =I7/SUM($I$6:$I$13) -> 0.045555556 | K7: 4500 | L7: =I7/K7 -> 0.0036444444
B8: Asia | C8: 80 | D8: 70 | E8: 75 | F8: 80 | G8: 76 | I8: =AVERAGE(C8:G8) -> 76.2 | J8: =I8/SUM($I$6:$I$13) -> 0.21166667 | K8: 35000 | L8: =I8/K8 -> 0.0021771429
B9: Europa Occidental | C9: 40 | D9: 15 | E9: 10 | F9: 25 | G9: 15 | I9: =AVERAGE(C9:G9) -> 21 | J9: =I9/SUM($I$6:$I$13) -> 0.058333333 | K9: 12000 | L9: =I9/K9 -> 0.00175
B10: Europa Meridional | C10: 5 | D10: 12 | E10: 8 | F10: 10 | G10: 7 | I10: =AVERAGE(C10:G10) -> 8.4 | J10: =I10/SUM($I$6:$I$13) -> 0.023333333 | K10: 4500 | L10: =I10/K10 -> 0.0018666667
B11: Europa Oriental | C11: 5 | D11: 5 | E11: 95 | F11: 5 | G11: 3 | I11: =AVERAGE(C11:G11) -> 22.6 | J11: =I11/SUM($I$6:$I$13) -> 0.062777778 | K11: 6000 | L11: =I11/K11 -> 0.0037666667
B12: África | C12: 5 | D12: 8 | E12: 6 | F12: 7 | G12: 8 | I12: =AVERAGE(C12:G12) -> 6.8 | J12: =I12/SUM($I$6:$I$13) -> 0.018888889 | K12: 3000 | L12: =I12/K12 -> 0.0022666667
B13: Oceanía y Resto | C13: 15 | D13: 20 | E13: 10 | F13: 12 | G13: 11 | I13: =AVERAGE(C13:G13) -> 13.6 | J13: =I13/SUM($I$6:$I$13) -> 0.037777778 | K13: 2000 | L13: =I13/K13 -> 0.0068
B14: TOTAL | C14: =SUM(C6:C13) -> 330 | D14: =SUM(D6:D13) -> 310 | E14: =SUM(E6:E13) -> 411 | F14: =SUM(F6:F13) -> 439 | G14: =SUM(G6:G13) -> 310 | H14: =SUM(H6:H13) -> 0 | I14: =SUM(I6:I13) -> 360 | J14: =SUM(J6:J13) -> 1 | K14: =SUM(K6:K13) -> 100300 | L14: =I14/K14 -> 0.0035892323
B17: Pérdidas Aseguradas y Brecha de Protección ($B)
B18: Región | C18: 2021 | D18: 2022 | E18: 2023 | F18: 2024 | G18: 2025 | H18: Promedio | I18: Brecha Protección
B19: Norteamérica | C19: 90 | D19: 100 | E19: 100 | F19: 117 | G19: 95 | I19: =AVERAGE(C19:G19) -> 100.4 | J19: =1-I19/I6 -> 0.48512821
B20: Sudamérica | C20: 3 | D20: 4 | E20: 3 | F20: 5 | G20: 6 | I20: =AVERAGE(C20:G20) -> 4.2 | J20: =1-I20/I7 -> 0.74390244
B21: Asia | C21: 8 | D21: 8 | E21: 7 | F21: 9 | G21: 9 | I21: =AVERAGE(C21:G21) -> 8.2 | J21: =1-I21/I8 -> 0.89238845
B22: Europa Occidental | C22: 15 | D22: 6 | E22: 4 | F22: 10 | G22: 6 | I22: =AVERAGE(C22:G22) -> 8.2 | J22: =1-I22/I9 -> 0.60952381
B23: Europa Meridional | C23: 2 | D23: 4 | E23: 3 | F23: 4 | G23: 3 | I23: =AVERAGE(C23:G23) -> 3.2 | J23: =1-I23/I10 -> 0.61904762
B24: Europa Oriental | C24: 1 | D24: 1 | E24: 5 | F24: 1 | G24: 1 | I24: =AVERAGE(C24:G24) -> 1.8 | J24: =1-I24/I11 -> 0.92035398
B25: África | C25: 1 | D25: 1 | E25: 1 | F25: 1 | G25: 1 | I25: =AVERAGE(C25:G25) -> 1 | J25: =1-I25/I12 -> 0.85294118
B26: Oceanía y Resto | C26: 5 | D26: 8 | E26: 4 | F26: 5 | G26: 5 | I26: =AVERAGE(C26:G26) -> 5.4 | J26: =1-I26/I13 -> 0.60294118

Sheet Escenarios
B2: Comparativa de Escenarios
B3: Resultados bajo escenarios conservador, base y optimista.
B5: Parámetros por Escenario
B6: Parámetro | C6: Conservador | D6: Base | E6: Optimista
B7: % Reducción de pérdidas | C7: 0.1 | D7: 0.2 | E7: 0.3
B8: % Ahorro first responders | C8: 0.1 | D8: 0.2 | E8: 0.3
B9: Años de adopción | C9: 5 | D9: 4 | E9: 3
B10: Tasa de descuento | C10: 0.07 | D10: 0.06 | E10: 0.05
B11: Horizonte (años) | C11: 10 | D11: 10 | E11: 10
B13: Resultados Financieros Globales (10 años, $B)
B14: Métrica | C14: Conservador | D14: Base | E14: Optimista | F14: Unidad
B15: Pérdidas promedio anual ($B) | C15: ='Datos Históricos'!I14 -> 360 | D15: ='Datos Históricos'!I14 -> 360 | E15: ='Datos Históricos'!I14 -> 360 | F15: $B
B16: Pérdidas evitadas 10 años ($B) | C16: ='Datos Históricos'!I14*0.08*10 -> 288 | D16: ='Datos Históricos'!I14*0.17*10 -> 612 | E16: ='Datos Históricos'!I14*0.27*10 -> 972 | F16: $B
B17: Ahorro first responders 10 años ($B) | C17: ='Datos Históricos'!I14*0.08*0.08*10 -> 23.04 | D17: ='Datos Históricos'!I14*0.08*0.17*10 -> 48.96 | E17: ='Datos Históricos'!I14*0.08*0.27*10 -> 77.76 | F17: $B
B18: Beneficio total 10 años ($B) | C18: =C16+C17 -> 311.04 | D18: =D16+D17 -> 660.96 | E18: =E16+E17 -> 1049.76 | F18: $B
B19: Coste total EWS ($B) | C19: =SUM(Supuestos!C26:C33)*(1+0.15*10) -> 91.25 | D19: =SUM(Supuestos!C26:C33)*(1+0.15*10) -> 91.25 | E19: =SUM(Supuestos!C26:C33)*(1+0.15*10) -> 91.25 | F19: $B
B20: ROI proyectado | C20: =(C18-C19)/C19 -> 2.4086575 | D20: =(D18-D19)/D19 -> 6.2433973 | E20: =(E18-E19)/E19 -> 10.504219 | F20: %
B21: BCR (Beneficio/Coste) | C21: =C18/C19 -> 3.4086575 | D21: =D18/D19 -> 7.2433973 | E21: =E18/E19 -> 11.504219 | F21: x
B22: Reducción de pérdidas sobre PIB | C22: =C16/SUM(Supuestos!E26:E33) -> 0.0028713858 | D22: =D16/SUM(Supuestos!E26:E33) -> 0.0061016949 | E22: =E16/SUM(Supuestos!E26:E33) -> 0.0096909272 | F22: %
B23: Payback estimado (años) | C23: 3.2 | D23: 1.7 | E23: 1 | F23: años

Sheet Proyecciones
B2: Proyecciones a 10 Años por Región (Escenario Base)
B3: Proyección anual de pérdidas evitadas, ahorro en first responders y flujo neto.
B5: Factor de Adopción por Región (Base)
B6: Región | E6: Factor Adopción Prom.
B7: Norteamérica | E7: 0.17
B8: Sudamérica | E8: 0.17
B9: Asia | E9: 0.17
B10: Europa Occidental | E10: 0.17
B11: Europa Meridional | E11: 0.17
B12: Europa Oriental | E12: 0.17
B13: África | E13: 0.17
B14: Oceanía y Resto | E14: 0.17
B17: Proyección Anual Detallada (10 años, Escenario Base)
B18: Métrica / Región | C18: 2026 | D18: 2027 | E18: 2028 | F18: 2029 | G18: 2030 | H18: 2031 | I18: 2032 | J18: 2033 | K18: 2034 | L18: 2035 | M18: Total 10 años | N18: VAN (6%)
B19: Norteamérica
B20: Pérdidas evitadas ($B) | C20: ='Datos Históricos'!I6*0.05 -> 9.75 | D20: ='Datos Históricos'!I6*0.1 -> 19.5 | E20: ='Datos Históricos'!I6*0.15 -> 29.25 | F20: ='Datos Históricos'!I6*0.2 -> 39 | G20: ='Datos Históricos'!I6*0.2 -> 39 | H20: ='Datos Históricos'!I6*0.2 -> 39 | I20: ='Datos Históricos'!I6*0.2 -> 39 | J20: ='Datos Históricos'!I6*0.2 -> 39 | K20: ='Datos Históricos'!I6*0.2 -> 39 | L20: ='Datos Históricos'!I6*0.2 -> 39 | M20: =SUM(C20:L20) -> 331.5 | N20: =NPV(0.06,C20:L20) -> 233.90784
B21: Ahorro first responders ($B) | C21: ='Datos Históricos'!I6*0.08*0.05 -> 0.78 | D21: ='Datos Históricos'!I6*0.08*0.1 -> 1.56 | E21: ='Datos Históricos'!I6*0.08*0.15 -> 2.34 | F21: ='Datos Históricos'!I6*0.08*0.2 -> 3.12 | G21: ='Datos Históricos'!I6*0.08*0.2 -> 3.12 | H21: ='Datos Históricos'!I6*0.08*0.2 -> 3.12 | I21: ='Datos Históricos'!I6*0.08*0.2 -> 3.12 | J21: ='Datos Históricos'!I6*0.08*0.2 -> 3.12 | K21: ='Datos Históricos'!I6*0.08*0.2 -> 3.12 | L21: ='Datos Históricos'!I6*0.08*0.2 -> 3.12 | M21: =SUM(C21:L21) -> 26.52 | N21: =NPV(0.06,C21:L21) -> 18.712627
B22: Beneficio total ($B) | C22: =C20+C21 -> 10.53 | D22: =D20+D21 -> 21.06 | E22: =E20+E21 -> 31.59 | F22: =F20+F21 -> 42.12 | G22: =G20+G21 -> 42.12 | H22: =H20+H21 -> 42.12 | I22: =I20+I21 -> 42.12 | J22: =J20+J21 -> 42.12 | ... L22: =L20+L21 -> 42.12 | M22: =SUM(C22:L22) -> 358.02 | N22: =NPV(0.06,C22:L22) -> 252.62046
B23: Costes EWS ($B) | C23: =Supuestos!C26+Supuestos!C26*0.15 -> 9.2 | D23: =Supuestos!C26*0.15 -> 1.2 | E23: =Supuestos!C26*0.15 -> 1.2 | F23: =Supuestos!C26*0.15 -> 1.2 | G23: =Supuestos!C26*0.15 -> 1.2 | H23: =Supuestos!C26*0.15 -> 1.2 | I23: =Supuestos!C26*0.15 -> 1.2 | J23: =Supuestos!C26*0.15 -> 1.2 | K23: =Supuestos!C26*0.15 -> 1.2 | L23: =Supuestos!C26*0.15 -> 1.2 | M23: =SUM(C23:L23) -> 20 | N23: =NPV(0.06,C23:L23) -> 16.379274
B24: Flujo neto ($B) | C24: =C22-C23 -> 1.33 | D24: =D22-D23 -> 19.86 | E24: =E22-E23 -> 30.39 | F24: =F22-F23 -> 40.92 | G24: =G22-G23 -> 40.92 | H24: =H22-H23 -> 40.92 | I24: =I22-I23 -> 40.92 | J24: =J22-J23 -> 40.92 | ... L24: =L22-L23 -> 40.92 | M24: =SUM(C24:L24) -> 338.02 | N24: =NPV(0.06,C24:L24) -> 236.24119
B26: Sudamérica
B27: Pérdidas evitadas ($B) | C27: ='Datos Históricos'!I7*0.05 -> 0.82 | D27: ='Datos Históricos'!I7*0.1 -> 1.64 | E27: ='Datos Históricos'!I7*0.15 -> 2.46 | F27: ='Datos Históricos'!I7*0.2 -> 3.28 | G27: ='Datos Históricos'!I7*0.2 -> 3.28 | H27: ='Datos Históricos'!I7*0.2 -> 3.28 | I27: ='Datos Históricos'!I7*0.2 -> 3.28 | J27: ='Datos Históricos'!I7*0.2 -> 3.28 | K27: ='Datos Históricos'!I7*0.2 -> 3.28 | L27: ='Datos Históricos'!I7*0.2 -> 3.28 | M27: =SUM(C27:L27) -> 27.88 | N27: =NPV(0.06,C27:L27) -> 19.672249
B28: Ahorro first responders ($B) | C28: ='Datos Históricos'!I7*0.08*0.05 -> 0.0656 | D28: ='Datos Históricos'!I7*0.08*0.1 -> 0.1312 | E28: ='Datos Históricos'!I7*0.08*0.15 -> 0.1968 | F28: ='Datos Históricos'!I7*0.08*0.2 -> 0.2624 | G28: ='Datos Históricos'!I7*0.08*0.2 -> 0.2624 | H28: ='Datos Históricos'!I7*0.08*0.2 -> 0.2624 | I28: ='Datos Históricos'!I7*0.08*0.2 -> 0.2624 | J28: ='Datos Históricos'!I7*0.08*0.2 -> 0.2624 | K28: ='Datos Históricos'!I7*0.08*0.2 -> 0.2624 | L28: ='Datos Históricos'!I7*0.08*0.2 -> 0.2624 | M28: =SUM(C28:L28) -> 2.2304 | N28: =NPV(0.06,C28:L28) -> 1.5737799
B29: Beneficio total ($B) | C29: =C27+C28 -> 0.8856 | D29: =D27+D28 -> 1.7712 | E29: =E27+E28 -> 2.6568 | F29: =F27+F28 -> 3.5424 | G29: =G27+G28 -> 3.5424 | H29: =H27+H28 -> 3.5424 | I29: =I27+I28 -> 3.5424 | J29: =J27+J28 -> 3.5424 | ... L29: =L27+L28 -> 3.5424 | M29: =SUM(C29:L29) -> 30.1104 | N29: =NPV(0.06,C29:L29) -> 21.246029
B30: Costes EWS ($B) | C30: =Supuestos!C27+Supuestos!C27*0.15 -> 3.45 | D30: =Supuestos!C27*0.15 -> 0.45 | E30: =Supuestos!C27*0.15 -> 0.45 | F30: =Supuestos!C27*0.15 -> 0.45 | G30: =Supuestos!C27*0.15 -> 0.45 | H30: =Supuestos!C27*0.15 -> 0.45 | I30: =Supuestos!C27*0.15 -> 0.45 | J30: =Supuestos!C27*0.15 -> 0.45 | K30: =Supuestos!C27*0.15 -> 0.45 | L30: =Supuestos!C27*0.15 -> 0.45 | M30: =SUM(C30:L30) -> 7.5 | N30: =NPV(0.06,C30:L30) -> 6.1422279
B31: Flujo neto ($B) | C31: =C29-C30 -> -2.5644 | D31: =D29-D30 -> 1.3212 | E31: =E29-E30 -> 2.2068 | F31: =F29-F30 -> 3.0924 | G31: =G29-G30 -> 3.0924 | H31: =H29-H30 -> 3.0924 | I31: =I29-I30 -> 3.0924 | J31: =J29-J30 -> 3.0924 | ... L31: =L29-L30 -> 3.0924 | M31: =SUM(C31:L31) -> 22.6104 | N31: =NPV(0.06,C31:L31) -> 15.103801
B33: Asia
B34: Pérdidas evitadas ($B) | C34: ='Datos Históricos'!I8*0.05 -> 3.81 | D34: ='Datos Históricos'!I8*0.1 -> 7.62 | E34: ='Datos Históricos'!I8*0.15 -> 11.43 | F34: ='Datos Históricos'!I8*0.2 -> 15.24 | G34: ='Datos Históricos'!I8*0.2 -> 15.24 | H34: ='Datos Históricos'!I8*0.2 -> 15.24 | I34: ='Datos Históricos'!I8*0.2 -> 15.24 | J34: ='Datos Históricos'!I8*0.2 -> 15.24 | K34: ='Datos Históricos'!I8*0.2 -> 15.24 | L34: ='Datos Históricos'!I8*0.2 -> 15.24 | M34: =SUM(C34:L34) -> 129.54 | N34: =NPV(0.06,C34:L34) -> 91.403985
B35: Ahorro first responders ($B) | C35: ='Datos Históricos'!I8*0.08*0.05 -> 0.3048 | D35: ='Datos Históricos'!I8*0.08*0.1 -> 0.6096 | E35: ='Datos Históricos'!I8*0.08*0.15 -> 0.9144 | F35: ='Datos Históricos'!I8*0.08*0.2 -> 1.2192 | G35: ='Datos Históricos'!I8*0.08*0.2 -> 1.2192 | H35: ='Datos Históricos'!I8*0.08*0.2 -> 1.2192 | I35: ='Datos Históricos'!I8*0.08*0.2 -> 1.2192 | J35: ='Datos Históricos'!I8*0.08*0.2 -> 1.2192 | K35: ='Datos Históricos'!I8*0.08*0.2 -> 1.2192 | L35: ='Datos Históricos'!I8*0.08*0.2 -> 1.2192 | M35: =SUM(C35:L35) -> 10.3632 | N35: =NPV(0.06,C35:L35) -> 7.3123188
B36: Beneficio total ($B) | C36: =C34+C35 -> 4.1148 | D36: =D34+D35 -> 8.2296 | E36: =E34+E35 -> 12.3444 | F36: =F34+F35 -> 16.4592 | G36: =G34+G35 -> 16.4592 | H36: =H34+H35 -> 16.4592 | I36: =I34+I35 -> 16.4592 | J36: =J34+J35 -> 16.4592 | ... L36: =L34+L35 -> 16.4592 | M36: =SUM(C36:L36) -> 139.9032 | N36: =NPV(0.06,C36:L36) -> 98.716304
B37: Costes EWS ($B) | C37: =Supuestos!C28+Supuestos!C28*0.15 -> 11.5 | D37: =Supuestos!C28*0.15 -> 1.5 | E37: =Supuestos!C28*0.15 -> 1.5 | F37: =Supuestos!C28*0.15 -> 1.5 | G37: =Supuestos!C28*0.15 -> 1.5 | H37: =Supuestos!C28*0.15 -> 1.5 | I37: =Supuestos!C28*0.15 -> 1.5 | J37: =Supuestos!C28*0.15 -> 1.5 | K37: =Supuestos!C28*0.15 -> 1.5 | L37: =Supuestos!C28*0.15 -> 1.5 | M37: =SUM(C37:L37) -> 25 | N37: =NPV(0.06,C37:L37) -> 20.474093
B38: Flujo neto ($B) | C38: =C36-C37 -> -7.3852 | D38: =D36-D37 -> 6.7296 | E38: =E36-E37 -> 10.8444 | F38: =F36-F37 -> 14.9592 | G38: =G36-G37 -> 14.9592 | H38: =H36-H37 -> 14.9592 | I38: =I36-I37 -> 14.9592 | J38: =J36-J37 -> 14.9592 | ... L38: =L36-L37 -> 14.9592 | M38: =SUM(C38:L38) -> 114.9032 | N38: =NPV(0.06,C38:L38) -> 78.242211
B40: Europa Occidental
B41: Pérdidas evitadas ($B) | C41: ='Datos Históricos'!I9*0.05 -> 1.05 | D41: ='Datos Históricos'!I9*0.1 -> 2.1 | E41: ='Datos Históricos'!I9*0.15 -> 3.15 | F41: ='Datos Históricos'!I9*0.2 -> 4.2 | G41: ='Datos Históricos'!I9*0.2 -> 4.2 | H41: ='Datos Históricos'!I9*0.2 -> 4.2 | I41: ='Datos Históricos'!I9*0.2 -> 4.2 | J41: ='Datos Históricos'!I9*0.2 -> 4.2 | K41: ='Datos Históricos'!I9*0.2 -> 4.2 | L41: ='Datos Históricos'!I9*0.2 -> 4.2 | M41: =SUM(C41:L41) -> 35.7 | N41: =NPV(0.06,C41:L41) -> 25.190075
B42: Ahorro first responders ($B) | C42: ='Datos Históricos'!I9*0.08*0.05 -> 0.084 | D42: ='Datos Históricos'!I9*0.08*0.1 -> 0.168 | E42: ='Datos Históricos'!I9*0.08*0.15 -> 0.252 | F42: ='Datos Históricos'!I9*0.08*0.2 -> 0.336 | G42: ='Datos Históricos'!I9*0.08*0.2 -> 0.336 | H42: ='Datos Históricos'!I9*0.08*0.2 -> 0.336 | I42: ='Datos Históricos'!I9*0.08*0.2 -> 0.336 | J42: ='Datos Históricos'!I9*0.08*0.2 -> 0.336 | K42: ='Datos Históricos'!I9*0.08*0.2 -> 0.336 | L42: ='Datos Históricos'!I9*0.08*0.2 -> 0.336 | M42: =SUM(C42:L42) -> 2.856 | N42: =NPV(0.06,C42:L42) -> 2.015206
B43: Beneficio total ($B) | C43: =C41+C42 -> 1.134 | D43: =D41+D42 -> 2.268 | E43: =E41+E42 -> 3.402 | F43: =F41+F42 -> 4.536 | G43: =G41+G42 -> 4.536 | H43: =H41+H42 -> 4.536 | I43: =I41+I42 -> 4.536 | J43: =J41+J42 -> 4.536 | ... L43: =L41+L42 -> 4.536 | M43: =SUM(C43:L43) -> 38.556 | N43: =NPV(0.06,C43:L43) -> 27.205281
B44: Costes EWS ($B) | C44: =Supuestos!C29+Supuestos!C29*0.15 -> 5.75 | D44: =Supuestos!C29*0.15 -> 0.75 | E44: =Supuestos!C29*0.15 -> 0.75 | F44: =Supuestos!C29*0.15 -> 0.75 | G44: =Supuestos!C29*0.15 -> 0.75 | H44: =Supuestos!C29*0.15 -> 0.75 | I44: =Supuestos!C29*0.15 -> 0.75 | J44: =Supuestos!C29*0.15 -> 0.75 | K44: =Supuestos!C29*0.15 -> 0.75 | L44: =Supuestos!C29*0.15 -> 0.75 | M44: =SUM(C44:L44) -> 12.5 | N44: =NPV(0.06,C44:L44) -> 10.237046
B45: Flujo neto ($B) | C45: =C43-C44 -> -4.616 | D45: =D43-D44 -> 1.518 | E45: =E43-E44 -> 2.652 | F45: =F43-F44 -> 3.786 | G45: =G43-G44 -> 3.786 | H45: =H43-H44 -> 3.786 | I45: =I43-I44 -> 3.786 | J45: =J43-J44 -> 3.786 | ... L45: =L43-L44 -> 3.786 | M45: =SUM(C45:L45) -> 26.056 | N45: =NPV(0.06,C45:L45) -> 16.968234
B47: Europa Meridional
B48: Pérdidas evitadas ($B) | C48: ='Datos Históricos'!I10*0.05 -> 0.42 | D48: ='Datos Históricos'!I10*0.1 -> 0.84 | E48: ='Datos Históricos'!I10*0.15 -> 1.26 | F48: ='Datos Históricos'!I10*0.2 -> 1.68 | G48: ='Datos Históricos'!I10*0.2 -> 1.68 | H48: ='Datos Históricos'!I10*0.2 -> 1.68 | I48: ='Datos Históricos'!I10*0.2 -> 1.68 | J48: ='Datos Históricos'!I10*0.2 -> 1.68 | K48: ='Datos Históricos'!I10*0.2 -> 1.68 | L48: ='Datos Históricos'!I10*0.2 -> 1.68 | M48: =SUM(C48:L48) -> 14.28 | N48: =NPV(0.06,C48:L48) -> 10.07603
...

Sheet Metodología y Fuentes
B2: Metodología y Fuentes
B4: 1. Metodología
B5: Pérdidas históricas | C5: Promedio de pérdidas económicas por región (2021-2025) según Aon, Swiss Re, Munich Re y EM-DAT. Incluye daños directos e indirectos.
B6: Inversión EWS | C6: Estimación basada en la iniciativa EW4All de la ONU ($3.1B global) escalada a sistemas comprehensivos por región.
B7: Reducción de pérdidas | C7: La ONU estima que 24h de aviso reduce daños hasta 30%. WMO/UNDRR documenta ROI de 10:1. Rango del modelo: 10%-30%.
B8: Ahorro first responders | C8: Costes de respuesta directa estimados como 8% de pérdidas económicas. El ahorro por EWS se modela igual al % de reducción de pérdidas.
B9: Ramp-up | C9: Adopción lineal durante 3-5 años hasta alcanzar efectividad completa.
B10: ROI | C10: (Beneficios - Costes) / Costes, sobre horizonte de 10 años.
B11: BCR | C11: Beneficio-Coste Ratio = Beneficios totales / Costes totales. Referencia: McKinsey 3:1-7:1, WMO 10:1.
B12: Reducción % PIB | C12: Pérdidas evitadas / PIB regional. Impacto macroeconómico de la inversión en EWS.
B13: Limitaciones | C13: Datos regionales son estimaciones de múltiples fuentes. Costes de first responders sin fuente global homogénea. No incluye beneficios intangibles (vidas salvadas, desplazamientos evitados).
B15: 2. Fuentes de Datos
B16: Fuente | C16: Descripción / Dato / URL
B17: Aon | C17: Climate and Catastrophe Insight 2026. Pérdidas globales 2025: $260B; 2024: $397B; aseguradas 2025: $127B; brecha protección: 51% URL: https://www.aon.com/en/insights/reports/climate-and-catastrophe-report
B18: Swiss Re Institute | C18: Norteamérica pérdidas aseguradas 2025: >$90B; 2024: $117B. SCS: $46B en 2025 URL: https://www.carriermanagement.com/news/2026/07/23/290308.htm
B19: NOAA | C19: EE.UU.: 27 desastres de mil millón+ en 2024, $182.7B en daños URL: https://coast.noaa.gov/states/fast-facts/hurricane-costs.html
B20: Munich Re | C20: Pérdidas globales 2024: ~$320B económicas, ~$140B aseguradas URL: https://www.munichre.com/en/company/media-relations/media-information-and-corporate-news/business-news/2026/riskscan-2026-survey.html
B21: EM-DAT / CRED | C21: 358 catástrofes en 2025; 16,000+ fallecidos; 110M afectados URL: https://www.emdat.be
B22: WMO / UNDRR | C22: EWS ROI 10:1; 24h de aviso reduce daños hasta 30% URL: https://www.itu.int/en/ITU-D/Emergency-Telecommunications/Pages/Early-Warnings-for-All-Initiative.aspx
B23: ONU (Secretario General) | C23: Mortalidad 6-8x menor con cobertura EWS URL: https://www.un.org/sg/en/content/sg/statements/2026-07-17/secretary-generals-remarks-the-dialogue-early-warnings-for-all-response-climate-change-the-world-artificial-intelligence-conference-meteorological-forum-delivered
B24: McKinsey / HBS | C24: BCR adaptación: 3:1 actual, 7:1 a 2°C URL: https://www.hbs.edu/environment/podcast/mckinsey-on-climate-adaptation-the-global-resilience-gap
B25: GOV.UK | C25: Adaptación BCR mediano ~4:1, rango 3:1-6:1 URL: https://www.gov.uk/government/publications/economic-opportunities-of-climate-adaptation-for-the-uk/economic-opportunities-of-climate-adaptation-for-the-uk
B26: LSE | C26: NZ EWS BCR 4.9:1 (conservador 2.4:1) URL: https://blogs.lse.ac.uk/impactofsocialsciences/2026/07/13/prevention-loses-budget-battles-wellbeing-economics-can-change-the-maths/
B27: UNDRR (Belice) | C27: EWS ROI hasta 6.8x en Belice URL: https://www.linkedin.com/posts/undrr_stronger-early-warning-systems-mean-safer-activity-7478236120628170752-KPoP
... B32: Aon (1H 2023) | C32: Desglose regional 1H 2023; EMEA $111B pérdidas URL: https://assets.aon.com/-/media/files/aon/capabilities/reinsurance/global-catastrophe-recap-1h-2023.pdf
B34: 3. Notas
B35: • Las celdas en azul son inputs editables. Modifíquelas para adaptar el modelo.
B36: • Las fórmulas en negro se recalculan automáticamente.
B37: • Los enlaces en verde referencian datos de otras hojas del libro.
B38: • Los datos regionales son estimaciones de múltiples fuentes y pueden no coincidir exactamente con totales globales publicados.
B39: • El modelo no incluye beneficios intangibles (vidas salvadas, desplazamientos evitados, continuidad educativa).
B40: • Para análisis de sensibilidad, modifique los parámetros en la hoja Supuestos.
B41: • El escenario Base asume: 20% reducción de pérdidas, 4 años de ramp-up, 6% tasa de descuento.
